2019-07-31 22:12:17,399 INFO: Microblog startup [in D:\Flask\microblog\app\__init__.py:44]
2019-07-31 22:26:01,362 INFO: Microblog startup [in D:\Flask\microblog\app\__init__.py:44]
2019-07-31 22:26:29,871 INFO: Microblog startup [in D:\Flask\microblog\app\__init__.py:44]
2019-07-31 22:26:37,412 INFO: Microblog startup [in D:\Flask\microblog\app\__init__.py:44]
2019-07-31 23:02:53,430 INFO: Microblog startup [in D:\Flask\microblog\app\__init__.py:44]
2019-07-31 23:04:13,733 INFO: Microblog startup [in D:\Flask\microblog\app\__init__.py:44]
2019-07-31 23:05:45,233 INFO: Microblog startup [in D:\Flask\microblog\app\__init__.py:44]
2019-07-31 23:18:08,646 INFO: Microblog startup [in D:\Flask\microblog\app\__init__.py:44]
2019-08-01 11:37:48,890 INFO: Microblog startup [in D:\Flask\microblog\app\__init__.py:44]
2019-08-01 11:39:16,924 INFO: Microblog startup [in D:\Flask\microblog\app\__init__.py:44]
2019-08-01 11:39:20,579 ERROR: Exception on /index [GET] [in d:\flask\microblog\venv\lib\site-packages\flask\app.py:1891]
Traceback (most recent call last):
  File "d:\flask\microblog\venv\lib\site-packages\flask\app.py", line 2446, in wsgi_app
    response = self.full_dispatch_request()
  File "d:\flask\microblog\venv\lib\site-packages\flask\app.py", line 1951, in full_dispatch_request
    rv = self.handle_user_exception(e)
  File "d:\flask\microblog\venv\lib\site-packages\flask\app.py", line 1820, in handle_user_exception
    reraise(exc_type, exc_value, tb)
  File "d:\flask\microblog\venv\lib\site-packages\flask\_compat.py", line 39, in reraise
    raise value
  File "d:\flask\microblog\venv\lib\site-packages\flask\app.py", line 1949, in full_dispatch_request
    rv = self.dispatch_request()
  File "d:\flask\microblog\venv\lib\site-packages\flask\app.py", line 1935, in dispatch_request
    return self.view_functions[rule.endpoint](**req.view_args)
  File "d:\flask\microblog\venv\lib\site-packages\flask_login\utils.py", line 261, in decorated_view
    return func(*args, **kwargs)
  File "D:\Flask\microblog\app\routes.py", line 28, in index
    return render_template('index.html', title='Home', user=user, posts=posts, form=form)
  File "d:\flask\microblog\venv\lib\site-packages\flask\templating.py", line 140, in render_template
    ctx.app,
  File "d:\flask\microblog\venv\lib\site-packages\flask\templating.py", line 120, in _render
    rv = template.render(context)
  File "d:\flask\microblog\venv\lib\site-packages\jinja2\asyncsupport.py", line 76, in render
    return original_render(self, *args, **kwargs)
  File "d:\flask\microblog\venv\lib\site-packages\jinja2\environment.py", line 1008, in render
    return self.environment.handle_exception(exc_info, True)
  File "d:\flask\microblog\venv\lib\site-packages\jinja2\environment.py", line 780, in handle_exception
    reraise(exc_type, exc_value, tb)
  File "d:\flask\microblog\venv\lib\site-packages\jinja2\_compat.py", line 37, in reraise
    raise value.with_traceback(tb)
  File "D:\Flask\microblog\app\templates\index.html", line 1, in top-level template code
    {% extends "base.html" %}
  File "D:\Flask\microblog\app\templates\base.html", line 31, in top-level template code
    {% block content %}{% endblock %}
  File "D:\Flask\microblog\app\templates\index.html", line 15, in block "content"
    <p>{{ for.submit() }}</p>
  File "d:\flask\microblog\venv\lib\site-packages\jinja2\environment.py", line 430, in getattr
    return getattr(obj, attribute)
jinja2.exceptions.UndefinedError: 'for' is undefined
2019-08-01 11:40:12,891 INFO: Microblog startup [in D:\Flask\microblog\app\__init__.py:44]
2019-08-01 11:41:12,878 ERROR: Exception on /unfollow/akovinenko [GET] [in d:\flask\microblog\venv\lib\site-packages\flask\app.py:1891]
Traceback (most recent call last):
  File "d:\flask\microblog\venv\lib\site-packages\flask\app.py", line 2446, in wsgi_app
    response = self.full_dispatch_request()
  File "d:\flask\microblog\venv\lib\site-packages\flask\app.py", line 1951, in full_dispatch_request
    rv = self.handle_user_exception(e)
  File "d:\flask\microblog\venv\lib\site-packages\flask\app.py", line 1820, in handle_user_exception
    reraise(exc_type, exc_value, tb)
  File "d:\flask\microblog\venv\lib\site-packages\flask\_compat.py", line 39, in reraise
    raise value
  File "d:\flask\microblog\venv\lib\site-packages\flask\app.py", line 1949, in full_dispatch_request
    rv = self.dispatch_request()
  File "d:\flask\microblog\venv\lib\site-packages\flask\app.py", line 1935, in dispatch_request
    return self.view_functions[rule.endpoint](**req.view_args)
  File "d:\flask\microblog\venv\lib\site-packages\flask_login\utils.py", line 261, in decorated_view
    return func(*args, **kwargs)
  File "D:\Flask\microblog\app\routes.py", line 116, in unfollow
    current_user.unfollow(username)
  File "D:\Flask\microblog\app\models.py", line 42, in unfollow
    if self.is_following(user):
  File "D:\Flask\microblog\app\models.py", line 46, in is_following
    return self.followed.filter(followers.c.followed_id == user.id).count() > 0
AttributeError: 'str' object has no attribute 'id'
2019-08-01 11:43:27,582 INFO: Microblog startup [in D:\Flask\microblog\app\__init__.py:44]
2019-08-01 12:03:42,156 INFO: Microblog startup [in D:\Flask\microblog\app\__init__.py:44]
2019-08-01 12:03:45,574 ERROR: Exception on /index [GET] [in d:\flask\microblog\venv\lib\site-packages\flask\app.py:1891]
Traceback (most recent call last):
  File "d:\flask\microblog\venv\lib\site-packages\flask\app.py", line 2446, in wsgi_app
    response = self.full_dispatch_request()
  File "d:\flask\microblog\venv\lib\site-packages\flask\app.py", line 1951, in full_dispatch_request
    rv = self.handle_user_exception(e)
  File "d:\flask\microblog\venv\lib\site-packages\flask\app.py", line 1820, in handle_user_exception
    reraise(exc_type, exc_value, tb)
  File "d:\flask\microblog\venv\lib\site-packages\flask\_compat.py", line 39, in reraise
    raise value
  File "d:\flask\microblog\venv\lib\site-packages\flask\app.py", line 1949, in full_dispatch_request
    rv = self.dispatch_request()
  File "d:\flask\microblog\venv\lib\site-packages\flask\app.py", line 1935, in dispatch_request
    return self.view_functions[rule.endpoint](**req.view_args)
  File "d:\flask\microblog\venv\lib\site-packages\flask_login\utils.py", line 261, in decorated_view
    return func(*args, **kwargs)
  File "D:\Flask\microblog\app\routes.py", line 32, in index
    return render_template('index.html', title='Home', form=form, posts=posts.items, next_url=next_url, prev_url=prev_url)
AttributeError: 'list' object has no attribute 'items'
2019-08-01 12:05:25,929 INFO: Microblog startup [in D:\Flask\microblog\app\__init__.py:44]
2019-08-01 12:05:34,130 ERROR: Exception on /user/akovinenko [GET] [in d:\flask\microblog\venv\lib\site-packages\flask\app.py:1891]
Traceback (most recent call last):
  File "d:\flask\microblog\venv\lib\site-packages\flask\app.py", line 2446, in wsgi_app
    response = self.full_dispatch_request()
  File "d:\flask\microblog\venv\lib\site-packages\flask\app.py", line 1951, in full_dispatch_request
    rv = self.handle_user_exception(e)
  File "d:\flask\microblog\venv\lib\site-packages\flask\app.py", line 1820, in handle_user_exception
    reraise(exc_type, exc_value, tb)
  File "d:\flask\microblog\venv\lib\site-packages\flask\_compat.py", line 39, in reraise
    raise value
  File "d:\flask\microblog\venv\lib\site-packages\flask\app.py", line 1949, in full_dispatch_request
    rv = self.dispatch_request()
  File "d:\flask\microblog\venv\lib\site-packages\flask\app.py", line 1935, in dispatch_request
    return self.view_functions[rule.endpoint](**req.view_args)
  File "d:\flask\microblog\venv\lib\site-packages\flask_login\utils.py", line 261, in decorated_view
    return func(*args, **kwargs)
  File "D:\Flask\microblog\app\routes.py", line 86, in user
    return render_template('user.html', user=user, posts=posts, next_url=next_url, prev_url=prev_url)
  File "d:\flask\microblog\venv\lib\site-packages\flask\templating.py", line 140, in render_template
    ctx.app,
  File "d:\flask\microblog\venv\lib\site-packages\flask\templating.py", line 120, in _render
    rv = template.render(context)
  File "d:\flask\microblog\venv\lib\site-packages\jinja2\asyncsupport.py", line 76, in render
    return original_render(self, *args, **kwargs)
  File "d:\flask\microblog\venv\lib\site-packages\jinja2\environment.py", line 1008, in render
    return self.environment.handle_exception(exc_info, True)
  File "d:\flask\microblog\venv\lib\site-packages\jinja2\environment.py", line 780, in handle_exception
    reraise(exc_type, exc_value, tb)
  File "d:\flask\microblog\venv\lib\site-packages\jinja2\_compat.py", line 37, in reraise
    raise value.with_traceback(tb)
  File "D:\Flask\microblog\app\templates\user.html", line 1, in top-level template code
    {% extends "base.html" %}
  File "D:\Flask\microblog\app\templates\base.html", line 31, in top-level template code
    {% block content %}{% endblock %}
  File "D:\Flask\microblog\app\templates\user.html", line 23, in block "content"
    {% for post in posts %}
TypeError: 'Pagination' object is not iterable
2019-08-01 12:06:36,577 INFO: Microblog startup [in D:\Flask\microblog\app\__init__.py:44]
